<?xml version="1.0"?>
<sdf version="1.9">
  <model name="forklift_demo">
    <pose>0 0 0 0 0 0</pose>
    <self_collide>false</self_collide>
    <static>false</static>

    <link name="base_link">
      <pose>0 0 0.25 0 0 0</pose>
      <inertial>
        <mass>80.0</mass>
        <inertia>
          <ixx>8.0</ixx>
          <iyy>12.0</iyy>
          <izz>15.0</izz>
          <ixy>0.0</ixy>
          <ixz>0.0</ixz>
          <iyz>0.0</iyz>
        </inertia>
      </inertial>
      <collision name="base_collision">
        <geometry>
          <box>
            <size>1.2 0.8 0.32</size>
          </box>
        </geometry>
      </collision>
      <visual name="base_visual">
        <geometry>
          <box>
            <size>1.2 0.8 0.32</size>
          </box>
        </geometry>
        <material>
          <ambient>0.90 0.62 0.18 1.0</ambient>
          <diffuse>0.90 0.62 0.18 1.0</diffuse>
        </material>
      </visual>
    </link>

    <link name="front_left_wheel_link">
      <pose>0.42 0.35 0.18 0 0 0</pose>
      <inertial>
        <mass>1.0</mass>
        <inertia>
          <ixx>0.02</ixx>
          <iyy>0.01</iyy>
          <izz>0.02</izz>
          <ixy>0.0</ixy>
          <ixz>0.0</ixz>
          <iyz>0.0</iyz>
        </inertia>
      </inertial>
      <collision name="front_left_wheel_collision">
        <pose>0 0 0 1.57079632679 0 0</pose>
        <geometry>
          <cylinder>
            <radius>0.18</radius>
            <length>0.08</length>
          </cylinder>
        </geometry>
      </collision>
      <visual name="front_left_wheel_visual">
        <pose>0 0 0 1.57079632679 0 0</pose>
        <geometry>
          <cylinder>
            <radius>0.18</radius>
            <length>0.08</length>
          </cylinder>
        </geometry>
        <material>
          <ambient>0.12 0.12 0.12 1.0</ambient>
          <diffuse>0.12 0.12 0.12 1.0</diffuse>
        </material>
      </visual>
    </link>

    <link name="front_right_wheel_link">
      <pose>0.42 -0.35 0.18 0 0 0</pose>
      <inertial>
        <mass>1.0</mass>
        <inertia>
          <ixx>0.02</ixx>
          <iyy>0.01</iyy>
          <izz>0.02</izz>
          <ixy>0.0</ixy>
          <ixz>0.0</ixz>
          <iyz>0.0</iyz>
        </inertia>
      </inertial>
      <collision name="front_right_wheel_collision">
        <pose>0 0 0 1.57079632679 0 0</pose>
        <geometry>
          <cylinder>
            <radius>0.18</radius>
            <length>0.08</length>
          </cylinder>
        </geometry>
      </collision>
      <visual name="front_right_wheel_visual">
        <pose>0 0 0 1.57079632679 0 0</pose>
        <geometry>
          <cylinder>
            <radius>0.18</radius>
            <length>0.08</length>
          </cylinder>
        </geometry>
        <material>
          <ambient>0.12 0.12 0.12 1.0</ambient>
          <diffuse>0.12 0.12 0.12 1.0</diffuse>
        </material>
      </visual>
    </link>

    <joint name="front_left_wheel_joint" type="revolute">
      <parent>base_link</parent>
      <child>front_left_wheel_link</child>
      <axis>
        <xyz>0 1 0</xyz>
        <limit>
          <effort>40</effort>
          <velocity>20.0</velocity>
        </limit>
      </axis>
    </joint>

    <joint name="front_right_wheel_joint" type="revolute">
      <parent>base_link</parent>
      <child>front_right_wheel_link</child>
      <axis>
        <xyz>0 1 0</xyz>
        <limit>
          <effort>40</effort>
          <velocity>20.0</velocity>
        </limit>
      </axis>
    </joint>

    <link name="rear_steer_link">
      <pose>-0.42 0.0 0.18 0 0 0</pose>
      <inertial>
        <mass>0.5</mass>
        <inertia>
          <ixx>0.01</ixx>
          <iyy>0.01</iyy>
          <izz>0.01</izz>
          <ixy>0.0</ixy>
          <ixz>0.0</ixz>
          <iyz>0.0</iyz>
        </inertia>
      </inertial>
    </link>

    <joint name="rear_steering_joint" type="revolute">
      <parent>base_link</parent>
      <child>rear_steer_link</child>
      <axis>
        <xyz>0 0 1</xyz>
        <limit>
          <lower>-1.48353</lower>
          <upper>1.48353</upper>
          <effort>50</effort>
          <velocity>1.5</velocity>
        </limit>
      </axis>
    </joint>

    <link name="rear_drive_wheel_link">
      <pose>-0.42 0 0.18 0 0 0</pose>
      <inertial>
        <mass>2.0</mass>
        <inertia>
          <ixx>0.05</ixx>
          <iyy>0.02</iyy>
          <izz>0.05</izz>
          <ixy>0.0</ixy>
          <ixz>0.0</ixz>
          <iyz>0.0</iyz>
        </inertia>
      </inertial>
      <collision name="rear_drive_wheel_collision">
        <pose>0 0 0 1.57079632679 0 0</pose>
        <geometry>
          <cylinder>
            <radius>0.18</radius>
            <length>0.1</length>
          </cylinder>
        </geometry>
      </collision>
      <visual name="rear_drive_wheel_visual">
        <pose>0 0 0 1.57079632679 0 0</pose>
        <geometry>
          <cylinder>
            <radius>0.18</radius>
            <length>0.1</length>
          </cylinder>
        </geometry>
        <material>
          <ambient>0.10 0.10 0.10 1.0</ambient>
          <diffuse>0.10 0.10 0.10 1.0</diffuse>
        </material>
      </visual>
    </link>

    <joint name="rear_wheel_joint" type="revolute">
      <parent>rear_steer_link</parent>
      <child>rear_drive_wheel_link</child>
      <axis>
        <xyz>0 1 0</xyz>
        <limit>
          <effort>80</effort>
          <velocity>6.0</velocity>
        </limit>
      </axis>
    </joint>

    <link name="laser_link">
      <pose>0.2 0.0 0.55 0 0 0</pose>
      <inertial>
        <mass>0.2</mass>
        <inertia>
          <ixx>0.001</ixx>
          <iyy>0.001</iyy>
          <izz>0.001</izz>
          <ixy>0.0</ixy>
          <ixz>0.0</ixz>
          <iyz>0.0</iyz>
        </inertia>
      </inertial>
      <visual name="laser_visual">
        <geometry>
          <cylinder>
            <radius>0.05</radius>
            <length>0.04</length>
          </cylinder>
        </geometry>
        <material>
          <ambient>0.18 0.18 0.20 1.0</ambient>
          <diffuse>0.18 0.18 0.20 1.0</diffuse>
        </material>
      </visual>
      <sensor name="lidar" type="gpu_lidar">
        <topic>/scan</topic>
        <update_rate>12</update_rate>
        <always_on>true</always_on>
        <visualize>false</visualize>
        <gz_frame_id>laser_link</gz_frame_id>
        <lidar>
          <scan>
            <horizontal>
              <samples>720</samples>
              <resolution>1</resolution>
              <min_angle>-3.14159265359</min_angle>
              <max_angle>3.14159265359</max_angle>
            </horizontal>
          </scan>
          <range>
            <min>0.05</min>
            <max>10.0</max>
            <resolution>0.01</resolution>
          </range>
        </lidar>
      </sensor>
    </link>

    <joint name="laser_joint" type="fixed">
      <parent>base_link</parent>
      <child>laser_link</child>
    </joint>

    <plugin
      filename="gz-sim-velocity-control-system"
      name="gz::sim::systems::VelocityControl">
      <topic>/model/forklift_demo/cmd_vel</topic>
    </plugin>

    <plugin
      filename="gz-sim-odometry-publisher-system"
      name="ignition::gazebo::systems::OdometryPublisher">
      <odom_topic>/odom_gz</odom_topic>
      <tf_topic>/tf_gz</tf_topic>
      <odom_frame>odom</odom_frame>
      <robot_base_frame>base_link</robot_base_frame>
      <odom_publish_frequency>30</odom_publish_frequency>
      <dimensions>2</dimensions>
    </plugin>

    <plugin
      filename="gz-sim-joint-state-publisher-system"
      name="gz::sim::systems::JointStatePublisher">
      <topic>/joint_states_gz</topic>
      <joint_name>front_left_wheel_joint</joint_name>
      <joint_name>front_right_wheel_joint</joint_name>
      <joint_name>rear_steering_joint</joint_name>
      <joint_name>rear_wheel_joint</joint_name>
    </plugin>

    <plugin
      filename="gz-sim-joint-position-controller-system"
      name="gz::sim::systems::JointPositionController">
      <joint_name>rear_steering_joint</joint_name>
      <use_velocity_commands>true</use_velocity_commands>
      <topic>/forklift/rear_steering_cmd</topic>
    </plugin>

    <plugin
      filename="gz-sim-joint-controller-system"
      name="gz::sim::systems::JointController">
      <joint_name>rear_wheel_joint</joint_name>
      <topic>/forklift/rear_wheel_cmd</topic>
    </plugin>
  </model>
</sdf>
